"""
This file is part of The Discord Math Problem Bot Repo

This program is free software: you can redistribute it and/or modify
it under the terms of the GNU General Public License as published by
the Free Software Foundation, either version 3 of the License, or
(at your option) any later version.

This program is distributed in the hope that it will be useful,
but WITHOUT ANY WARRANTY; without even the implied warranty of
MERCHANTABILITY or FITNESS FOR A PARTICULAR PURPOSE.  See the
GNU General Public License for more details.

You should have received a copy of the GNU General Public License
along with this program.  If not, see <https://www.gnu.org/licenses/>.

Author: Samuel Guo (64931063+rf20008@users.noreply.github.com)
"""
import asyncio
import datetime
import logging
import traceback
from copy import deepcopy
from sys import exc_info, stderr
from time import asctime
import os

import disnake
from disnake.ext import commands
import subprocess
from ._error_logging import log_error
from .cooldowns import OnCooldown
from .custom_embeds import SuccessEmbed, ErrorEmbed, SimpleEmbed
from .problems_module.errors import LockedCacheException, LinearAlgebraUserInputErrorException
from helpful_modules.paginator_view import PaginatorView
from .the_documentation_file_loader import DocumentationFileLoader


def get_git_revision_hash() -> str:
    """A method that gets the git revision hash. Credit to https://stackoverflow.com/a/21901260 for the code :-)"""
    return subprocess.check_output(
        ["git", "rev-parse", "HEAD"], encoding="ascii", errors="ignore"
    ).strip()[
        :7
    ]  # [7:] is here because of the commit hash, the rest of this function is from stack overflow


async def base_on_error(
    inter: disnake.ApplicationCommandInteraction, error: BaseException | Exception
):
    """The base on_error event. Call this and use the dictionary as keyword arguments to print to the user"""

    if isinstance(error, BaseException) and not isinstance(error, Exception):
        # Errors that do not inherit from Exception are not meant to be caught
        await inter.bot.close()
        if exc_info()[0] is not None:
            raise
        raise error
    cause = None
    if error.__context__ is not None:
        cause = error.__context__

    if isinstance(cause, LockedCacheException) or isinstance(error, LockedCacheException):
        return {
            "content": "The bot's cache's lock is currently being held. Please try again later."
        }
    #print(isinstance(cause, LinearAlgebraUserInputErrorException))
    #print(type(cause))
    if isinstance(cause, LinearAlgebraUserInputErrorException) or isinstance(error, LinearAlgebraUserInputErrorException):
        print(cause.args)
        print(str(cause))
        return {"embed": ErrorEmbed(str(cause))}
    if isinstance(error, (OnCooldown, disnake.ext.commands.CommandOnCooldown)):
        # This is a cooldown exception
        content = f"This command is on cooldown; please retry **{disnake.utils.format_dt(disnake.utils.utcnow() + datetime.timedelta(seconds=error.retry_after), style='R')}**."
        return {"content": content, "delete_after": error.retry_after}
    if isinstance(error, (disnake.Forbidden,)):
        extra_content = """There was a 403 error. This means either
        1) You didn't give me enough permissions to function correctly, or
        2) There's a bug! If so, please report it!

        The error traceback is below."""
        error_traceback = "\n".join(traceback.format_exception(error))
        return {"content": extra_content + error_traceback}

    if isinstance(error, commands.NotOwner):
        return {"embed": ErrorEmbed("You are not the owner of this bot.")}
    if isinstance(error, disnake.ext.commands.errors.CheckFailure):
        return {"embed": ErrorEmbed(str(error))}


    # Embed = ErrorEmbed(custom_title="âš  Oh no! Error: " + str(type(error)), description=("Command raised an exception:" + str(error)))
    logging.error("Uh oh - an error occurred ", exc_info=exc_info())
    error_traceback = "\n".join(traceback.format_exception(error))
    print(
        "\n".join(traceback.format_exception(error)),  # python 3.10 only!
        file=stderr,
    )

    error_msg = """An error occurred!

    Steps you should do:
    1) Please report this bug to me! (Either create a github issue, or report it in the support server)
    2) If you are a programmer, please suggest a fix by creating a Pull Request.
    3) Please don't use this command until it gets fixed in a later update!

    The error traceback is shown below; this may be removed/DMed to the user in the future.

    """ # TODO: update when my support server becomes public & think about providing the traceback to the user
    traceback_msg = disnake.utils.escape_markdown(error_traceback)
    additional_error = ""
    try:
        await log_error(error)  # Log the error
    except Exception as log_error_exc:
        additional_error = (
            """Additionally, while trying to log this error, the following exception occurred: \n"""
            + disnake.utils.escape_markdown(
                "\n".join(traceback.format_exception(log_error_exc))
            )
        )

    try:
        embed = disnake.Embed(
            colour=disnake.Colour.red(),
            description=error_msg + traceback_msg + additional_error,
            title="Oh, no! An error occurred!",
        )
    except (TypeError, NameError) as e:
        # send as plain text
        plain_text = (
            """Oh no! An Exception occurred! And it couldn't be sent as an embed!```"""
        )
        plain_text += error_msg + traceback_msg + additional_error
        plain_text += f"```Time: {str(asctime())} Commit hash: {get_git_revision_hash()} The stack trace is shown for debugging purposes. The stack trace is also logged (and pushed), but should not contain identifying information (only code which is on github)"

        plain_text += f"Error that occurred while attempting to send it as an embed:"
        plain_text += disnake.utils.escape_markdown(
            "".join(traceback.format_exception(e))
        )[: -(1650 - len(plain_text))]
        the_new_exception = deepcopy(e)
        the_new_exception.__cause__ = error
        if len(plain_text) > 2000:
            # uh oh
            raise RuntimeError(
                "An error occurred; could not send it as an embed nor as plain text!"
            ) from the_new_exception

        return {"content": plain_text}
    footer = f"Time: {str(asctime())} Commit hash: {get_git_revision_hash()} The stack trace is shown for debugging purposes. The stack trace is also logged (and pushed), but should not contain identifying information (only code which is on github)"
    embed.set_footer(text=footer)
    if len(embed.description) < 2048:
        return {"embed": embed}
    paginator = PaginatorView.paginate(
        user_id=inter.author.id,
        text=error_msg,
        breaking_chars="\n",
        max_page_length=1900,
        special_color=disnake.Color.red()
    )
    paginator.add_pages(PaginatorView.break_into_pages(traceback_msg, max_page_length=1900, breaking_chars="\n"))
    if additional_error:
        paginator.add_pages(PaginatorView.break_into_pages(additional_error, max_page_length=1900, breaking_chars="\n"))
    accounted_for = len(error_msg) + len(traceback_msg) + len(additional_error)
    if len(embed.description) != accounted_for:
        paginator.add_pages(PaginatorView.break_into_pages(embed.description[accounted_for:], max_page_length=1900, breaking_chars="\n"))
    first_page = paginator.create_embed()
    return {"embed": first_page, "view": paginator}
