Thu Dec  9 03:56:24 2021

Traceback (most recent call last):
  File "/opt/virtualenvs/python3/lib/python3.8/site-packages/dislash/application_commands/slash_client.py", line 1275, in _on_slash_command
    await app_command.invoke(inter)
  File "/opt/virtualenvs/python3/lib/python3.8/site-packages/dislash/application_commands/slash_core.py", line 362, in invoke
    raise err
  File "/opt/virtualenvs/python3/lib/python3.8/site-packages/dislash/application_commands/slash_core.py", line 359, in invoke
    await self.invoke_children(interaction)
  File "/opt/virtualenvs/python3/lib/python3.8/site-packages/dislash/application_commands/slash_core.py", line 350, in invoke_children
    raise err
  File "/opt/virtualenvs/python3/lib/python3.8/site-packages/dislash/application_commands/slash_core.py", line 347, in invoke_children
    await subcmd._maybe_cog_call(self._cog, interaction, option)
  File "/opt/virtualenvs/python3/lib/python3.8/site-packages/dislash/application_commands/slash_core.py", line 112, in _maybe_cog_call
    return await self(cog, inter, **kwargs)
  File "/opt/virtualenvs/python3/lib/python3.8/site-packages/dislash/application_commands/core.py", line 72, in __call__
    return await self.func(*args, **kwargs)
  File "/home/runner/TheDiscordMathProblemBot/cogs/misc_commands_cog.py", line 362, in get_data
    str(await self._get_json_data_by_user(inter.author)),
  File "/home/runner/TheDiscordMathProblemBot/cogs/misc_commands_cog.py", line 342, in _get_json_data_by_user
    raw_data = await self.cache.get_all_by_author_id(author.id)
  File "/home/runner/TheDiscordMathProblemBot/helpful_modules/problems_module/cache.py", line 905, in get_all_by_author_id
    await cursor.execute(
  File "/opt/virtualenvs/python3/lib/python3.8/site-packages/aiosqlite/cursor.py", line 37, in execute
    await self._execute(self._cursor.execute, sql, parameters)
  File "/opt/virtualenvs/python3/lib/python3.8/site-packages/aiosqlite/cursor.py", line 31, in _execute
    return await self._conn._execute(fn, *args, **kwargs)
  File "/opt/virtualenvs/python3/lib/python3.8/site-packages/aiosqlite/core.py", line 129, in _execute
    return await future
  File "/opt/virtualenvs/python3/lib/python3.8/site-packages/aiosqlite/core.py", line 102, in run
    result = function()
ValueError: parameters are of unsupported type


Thu Dec  9 04:01:37 2021

Traceback (most recent call last):
  File "/opt/virtualenvs/python3/lib/python3.8/site-packages/dislash/application_commands/slash_client.py", line 1275, in _on_slash_command
    await app_command.invoke(inter)
  File "/opt/virtualenvs/python3/lib/python3.8/site-packages/dislash/application_commands/slash_core.py", line 362, in invoke
    raise err
  File "/opt/virtualenvs/python3/lib/python3.8/site-packages/dislash/application_commands/slash_core.py", line 359, in invoke
    await self.invoke_children(interaction)
  File "/opt/virtualenvs/python3/lib/python3.8/site-packages/dislash/application_commands/slash_core.py", line 350, in invoke_children
    raise err
  File "/opt/virtualenvs/python3/lib/python3.8/site-packages/dislash/application_commands/slash_core.py", line 347, in invoke_children
    await subcmd._maybe_cog_call(self._cog, interaction, option)
  File "/opt/virtualenvs/python3/lib/python3.8/site-packages/dislash/application_commands/slash_core.py", line 112, in _maybe_cog_call
    return await self(cog, inter, **kwargs)
  File "/opt/virtualenvs/python3/lib/python3.8/site-packages/dislash/application_commands/core.py", line 72, in __call__
    return await self.func(*args, **kwargs)
  File "/home/runner/TheDiscordMathProblemBot/cogs/misc_commands_cog.py", line 362, in get_data
    str(await self._get_json_data_by_user(inter.author)),
  File "/home/runner/TheDiscordMathProblemBot/cogs/misc_commands_cog.py", line 342, in _get_json_data_by_user
    raw_data = await self.cache.get_all_by_author_id(author.id)
  File "/home/runner/TheDiscordMathProblemBot/helpful_modules/problems_module/cache.py", line 904, in get_all_by_author_id
    await cursor.execute(
  File "/opt/virtualenvs/python3/lib/python3.8/site-packages/aiosqlite/cursor.py", line 37, in execute
    await self._execute(self._cursor.execute, sql, parameters)
  File "/opt/virtualenvs/python3/lib/python3.8/site-packages/aiosqlite/cursor.py", line 31, in _execute
    return await self._conn._execute(fn, *args, **kwargs)
  File "/opt/virtualenvs/python3/lib/python3.8/site-packages/aiosqlite/core.py", line 129, in _execute
    return await future
  File "/opt/virtualenvs/python3/lib/python3.8/site-packages/aiosqlite/core.py", line 102, in run
    result = function()
ValueError: parameters are of unsupported type


Thu Dec  9 04:02:30 2021

Traceback (most recent call last):
  File "/opt/virtualenvs/python3/lib/python3.8/site-packages/dislash/application_commands/slash_client.py", line 1275, in _on_slash_command
    await app_command.invoke(inter)
  File "/opt/virtualenvs/python3/lib/python3.8/site-packages/dislash/application_commands/slash_core.py", line 362, in invoke
    raise err
  File "/opt/virtualenvs/python3/lib/python3.8/site-packages/dislash/application_commands/slash_core.py", line 359, in invoke
    await self.invoke_children(interaction)
  File "/opt/virtualenvs/python3/lib/python3.8/site-packages/dislash/application_commands/slash_core.py", line 350, in invoke_children
    raise err
  File "/opt/virtualenvs/python3/lib/python3.8/site-packages/dislash/application_commands/slash_core.py", line 347, in invoke_children
    await subcmd._maybe_cog_call(self._cog, interaction, option)
  File "/opt/virtualenvs/python3/lib/python3.8/site-packages/dislash/application_commands/slash_core.py", line 112, in _maybe_cog_call
    return await self(cog, inter, **kwargs)
  File "/opt/virtualenvs/python3/lib/python3.8/site-packages/dislash/application_commands/core.py", line 72, in __call__
    return await self.func(*args, **kwargs)
  File "/home/runner/TheDiscordMathProblemBot/cogs/misc_commands_cog.py", line 362, in get_data
    str(await self._get_json_data_by_user(inter.author)),
  File "/home/runner/TheDiscordMathProblemBot/cogs/misc_commands_cog.py", line 342, in _get_json_data_by_user
    raw_data = await self.cache.get_all_by_author_id(author.id)
  File "/home/runner/TheDiscordMathProblemBot/helpful_modules/problems_module/cache.py", line 905, in get_all_by_author_id
    await cursor.execute(
  File "/opt/virtualenvs/python3/lib/python3.8/site-packages/aiosqlite/cursor.py", line 37, in execute
    await self._execute(self._cursor.execute, sql, parameters)
  File "/opt/virtualenvs/python3/lib/python3.8/site-packages/aiosqlite/cursor.py", line 31, in _execute
    return await self._conn._execute(fn, *args, **kwargs)
  File "/opt/virtualenvs/python3/lib/python3.8/site-packages/aiosqlite/core.py", line 129, in _execute
    return await future
  File "/opt/virtualenvs/python3/lib/python3.8/site-packages/aiosqlite/core.py", line 102, in run
    result = function()
ValueError: parameters are of unsupported type


Thu Dec  9 04:03:18 2021

Traceback (most recent call last):
  File "/opt/virtualenvs/python3/lib/python3.8/site-packages/dislash/application_commands/slash_client.py", line 1275, in _on_slash_command
    await app_command.invoke(inter)
  File "/opt/virtualenvs/python3/lib/python3.8/site-packages/dislash/application_commands/slash_core.py", line 362, in invoke
    raise err
  File "/opt/virtualenvs/python3/lib/python3.8/site-packages/dislash/application_commands/slash_core.py", line 359, in invoke
    await self.invoke_children(interaction)
  File "/opt/virtualenvs/python3/lib/python3.8/site-packages/dislash/application_commands/slash_core.py", line 350, in invoke_children
    raise err
  File "/opt/virtualenvs/python3/lib/python3.8/site-packages/dislash/application_commands/slash_core.py", line 347, in invoke_children
    await subcmd._maybe_cog_call(self._cog, interaction, option)
  File "/opt/virtualenvs/python3/lib/python3.8/site-packages/dislash/application_commands/slash_core.py", line 112, in _maybe_cog_call
    return await self(cog, inter, **kwargs)
  File "/opt/virtualenvs/python3/lib/python3.8/site-packages/dislash/application_commands/core.py", line 72, in __call__
    return await self.func(*args, **kwargs)
  File "/home/runner/TheDiscordMathProblemBot/cogs/misc_commands_cog.py", line 362, in get_data
    str(await self._get_json_data_by_user(inter.author)),
  File "/home/runner/TheDiscordMathProblemBot/cogs/misc_commands_cog.py", line 342, in _get_json_data_by_user
    raw_data = await self.cache.get_all_by_author_id(author.id)
  File "/home/runner/TheDiscordMathProblemBot/helpful_modules/problems_module/cache.py", line 917, in get_all_by_author_id
    await cursor.execute(
  File "/opt/virtualenvs/python3/lib/python3.8/site-packages/aiosqlite/cursor.py", line 37, in execute
    await self._execute(self._cursor.execute, sql, parameters)
  File "/opt/virtualenvs/python3/lib/python3.8/site-packages/aiosqlite/cursor.py", line 31, in _execute
    return await self._conn._execute(fn, *args, **kwargs)
  File "/opt/virtualenvs/python3/lib/python3.8/site-packages/aiosqlite/core.py", line 129, in _execute
    return await future
  File "/opt/virtualenvs/python3/lib/python3.8/site-packages/aiosqlite/core.py", line 102, in run
    result = function()
sqlite3.OperationalError: no such column: author


Thu Dec  9 17:42:50 2021

Traceback (most recent call last):
  File "/opt/virtualenvs/python3/lib/python3.8/site-packages/dislash/application_commands/slash_client.py", line 1275, in _on_slash_command
    await app_command.invoke(inter)
  File "/opt/virtualenvs/python3/lib/python3.8/site-packages/dislash/application_commands/slash_core.py", line 362, in invoke
    raise err
  File "/opt/virtualenvs/python3/lib/python3.8/site-packages/dislash/application_commands/slash_core.py", line 359, in invoke
    await self.invoke_children(interaction)
  File "/opt/virtualenvs/python3/lib/python3.8/site-packages/dislash/application_commands/slash_core.py", line 350, in invoke_children
    raise err
  File "/opt/virtualenvs/python3/lib/python3.8/site-packages/dislash/application_commands/slash_core.py", line 347, in invoke_children
    await subcmd._maybe_cog_call(self._cog, interaction, option)
  File "/opt/virtualenvs/python3/lib/python3.8/site-packages/dislash/application_commands/slash_core.py", line 112, in _maybe_cog_call
    return await self(cog, inter, **kwargs)
  File "/opt/virtualenvs/python3/lib/python3.8/site-packages/dislash/application_commands/core.py", line 72, in __call__
    return await self.func(*args, **kwargs)
  File "/home/runner/TheDiscordMathProblemBot/cogs/misc_commands_cog.py", line 362, in get_data
    str(await self._get_json_data_by_user(inter.author)),
  File "/home/runner/TheDiscordMathProblemBot/cogs/misc_commands_cog.py", line 342, in _get_json_data_by_user
    raw_data = await self.cache.get_all_by_author_id(author.id)
  File "/home/runner/TheDiscordMathProblemBot/helpful_modules/problems_module/cache.py", line 917, in get_all_by_author_id
    await cursor.execute(
  File "/opt/virtualenvs/python3/lib/python3.8/site-packages/aiosqlite/cursor.py", line 37, in execute
    await self._execute(self._cursor.execute, sql, parameters)
  File "/opt/virtualenvs/python3/lib/python3.8/site-packages/aiosqlite/cursor.py", line 31, in _execute
    return await self._conn._execute(fn, *args, **kwargs)
  File "/opt/virtualenvs/python3/lib/python3.8/site-packages/aiosqlite/core.py", line 129, in _execute
    return await future
  File "/opt/virtualenvs/python3/lib/python3.8/site-packages/aiosqlite/core.py", line 102, in run
    result = function()
sqlite3.OperationalError: no such column: author


Thu Dec  9 18:41:40 2021

Traceback (most recent call last):
  File "/opt/virtualenvs/python3/lib/python3.8/site-packages/dislash/application_commands/slash_client.py", line 1275, in _on_slash_command
    await app_command.invoke(inter)
  File "/opt/virtualenvs/python3/lib/python3.8/site-packages/dislash/application_commands/slash_core.py", line 362, in invoke
    raise err
  File "/opt/virtualenvs/python3/lib/python3.8/site-packages/dislash/application_commands/slash_core.py", line 359, in invoke
    await self.invoke_children(interaction)
  File "/opt/virtualenvs/python3/lib/python3.8/site-packages/dislash/application_commands/slash_core.py", line 350, in invoke_children
    raise err
  File "/opt/virtualenvs/python3/lib/python3.8/site-packages/dislash/application_commands/slash_core.py", line 347, in invoke_children
    await subcmd._maybe_cog_call(self._cog, interaction, option)
  File "/opt/virtualenvs/python3/lib/python3.8/site-packages/dislash/application_commands/slash_core.py", line 112, in _maybe_cog_call
    return await self(cog, inter, **kwargs)
  File "/opt/virtualenvs/python3/lib/python3.8/site-packages/dislash/application_commands/core.py", line 72, in __call__
    return await self.func(*args, **kwargs)
  File "/home/runner/TheDiscordMathProblemBot/cogs/misc_commands_cog.py", line 362, in get_data
    str(await self._get_json_data_by_user(inter.author)),
  File "/home/runner/TheDiscordMathProblemBot/cogs/misc_commands_cog.py", line 342, in _get_json_data_by_user
    raw_data = await self.cache.get_all_by_author_id(author.id)
  File "/home/runner/TheDiscordMathProblemBot/helpful_modules/problems_module/cache.py", line 917, in get_all_by_author_id
    await cursor.execute(
  File "/opt/virtualenvs/python3/lib/python3.8/site-packages/aiosqlite/cursor.py", line 37, in execute
    await self._execute(self._cursor.execute, sql, parameters)
  File "/opt/virtualenvs/python3/lib/python3.8/site-packages/aiosqlite/cursor.py", line 31, in _execute
    return await self._conn._execute(fn, *args, **kwargs)
  File "/opt/virtualenvs/python3/lib/python3.8/site-packages/aiosqlite/core.py", line 129, in _execute
    return await future
  File "/opt/virtualenvs/python3/lib/python3.8/site-packages/aiosqlite/core.py", line 102, in run
    result = function()
sqlite3.OperationalError: no such column: author


Thu Dec  9 18:41:42 2021

Traceback (most recent call last):
  File "/opt/virtualenvs/python3/lib/python3.8/site-packages/dislash/application_commands/slash_client.py", line 1275, in _on_slash_command
    await app_command.invoke(inter)
  File "/opt/virtualenvs/python3/lib/python3.8/site-packages/dislash/application_commands/slash_core.py", line 362, in invoke
    raise err
  File "/opt/virtualenvs/python3/lib/python3.8/site-packages/dislash/application_commands/slash_core.py", line 359, in invoke
    await self.invoke_children(interaction)
  File "/opt/virtualenvs/python3/lib/python3.8/site-packages/dislash/application_commands/slash_core.py", line 350, in invoke_children
    raise err
  File "/opt/virtualenvs/python3/lib/python3.8/site-packages/dislash/application_commands/slash_core.py", line 347, in invoke_children
    await subcmd._maybe_cog_call(self._cog, interaction, option)
  File "/opt/virtualenvs/python3/lib/python3.8/site-packages/dislash/application_commands/slash_core.py", line 112, in _maybe_cog_call
    return await self(cog, inter, **kwargs)
  File "/opt/virtualenvs/python3/lib/python3.8/site-packages/dislash/application_commands/core.py", line 72, in __call__
    return await self.func(*args, **kwargs)
  File "/home/runner/TheDiscordMathProblemBot/cogs/misc_commands_cog.py", line 362, in get_data
    str(await self._get_json_data_by_user(inter.author)),
  File "/home/runner/TheDiscordMathProblemBot/cogs/misc_commands_cog.py", line 342, in _get_json_data_by_user
    raw_data = await self.cache.get_all_by_author_id(author.id)
  File "/home/runner/TheDiscordMathProblemBot/helpful_modules/problems_module/cache.py", line 917, in get_all_by_author_id
    await cursor.execute(
  File "/opt/virtualenvs/python3/lib/python3.8/site-packages/aiosqlite/cursor.py", line 37, in execute
    await self._execute(self._cursor.execute, sql, parameters)
  File "/opt/virtualenvs/python3/lib/python3.8/site-packages/aiosqlite/cursor.py", line 31, in _execute
    return await self._conn._execute(fn, *args, **kwargs)
  File "/opt/virtualenvs/python3/lib/python3.8/site-packages/aiosqlite/core.py", line 129, in _execute
    return await future
  File "/opt/virtualenvs/python3/lib/python3.8/site-packages/aiosqlite/core.py", line 102, in run
    result = function()
sqlite3.OperationalError: no such column: author


Thu Dec  9 19:31:20 2021

Traceback (most recent call last):
  File "/opt/virtualenvs/python3/lib/python3.8/site-packages/dislash/application_commands/slash_client.py", line 1275, in _on_slash_command
    await app_command.invoke(inter)
  File "/opt/virtualenvs/python3/lib/python3.8/site-packages/dislash/application_commands/slash_core.py", line 362, in invoke
    raise err
  File "/opt/virtualenvs/python3/lib/python3.8/site-packages/dislash/application_commands/slash_core.py", line 359, in invoke
    await self.invoke_children(interaction)
  File "/opt/virtualenvs/python3/lib/python3.8/site-packages/dislash/application_commands/slash_core.py", line 350, in invoke_children
    raise err
  File "/opt/virtualenvs/python3/lib/python3.8/site-packages/dislash/application_commands/slash_core.py", line 347, in invoke_children
    await subcmd._maybe_cog_call(self._cog, interaction, option)
  File "/opt/virtualenvs/python3/lib/python3.8/site-packages/dislash/application_commands/slash_core.py", line 112, in _maybe_cog_call
    return await self(cog, inter, **kwargs)
  File "/opt/virtualenvs/python3/lib/python3.8/site-packages/dislash/application_commands/core.py", line 72, in __call__
    return await self.func(*args, **kwargs)
  File "/home/runner/TheDiscordMathProblemBot/cogs/misc_commands_cog.py", line 362, in get_data
    str(await self._get_json_data_by_user(inter.author)),
  File "/home/runner/TheDiscordMathProblemBot/cogs/misc_commands_cog.py", line 342, in _get_json_data_by_user
    raw_data = await self.cache.get_all_by_author_id(author.id)
  File "/home/runner/TheDiscordMathProblemBot/helpful_modules/problems_module/cache.py", line 917, in get_all_by_author_id
    await cursor.execute(
  File "/opt/virtualenvs/python3/lib/python3.8/site-packages/aiosqlite/cursor.py", line 37, in execute
    await self._execute(self._cursor.execute, sql, parameters)
  File "/opt/virtualenvs/python3/lib/python3.8/site-packages/aiosqlite/cursor.py", line 31, in _execute
    return await self._conn._execute(fn, *args, **kwargs)
  File "/opt/virtualenvs/python3/lib/python3.8/site-packages/aiosqlite/core.py", line 129, in _execute
    return await future
  File "/opt/virtualenvs/python3/lib/python3.8/site-packages/aiosqlite/core.py", line 102, in run
    result = function()
sqlite3.OperationalError: no such column: author


Thu Dec  9 19:33:18 2021

Traceback (most recent call last):
  File "/opt/virtualenvs/python3/lib/python3.8/site-packages/dislash/application_commands/slash_client.py", line 1275, in _on_slash_command
    await app_command.invoke(inter)
  File "/opt/virtualenvs/python3/lib/python3.8/site-packages/dislash/application_commands/slash_core.py", line 362, in invoke
    raise err
  File "/opt/virtualenvs/python3/lib/python3.8/site-packages/dislash/application_commands/slash_core.py", line 359, in invoke
    await self.invoke_children(interaction)
  File "/opt/virtualenvs/python3/lib/python3.8/site-packages/dislash/application_commands/slash_core.py", line 350, in invoke_children
    raise err
  File "/opt/virtualenvs/python3/lib/python3.8/site-packages/dislash/application_commands/slash_core.py", line 347, in invoke_children
    await subcmd._maybe_cog_call(self._cog, interaction, option)
  File "/opt/virtualenvs/python3/lib/python3.8/site-packages/dislash/application_commands/slash_core.py", line 112, in _maybe_cog_call
    return await self(cog, inter, **kwargs)
  File "/opt/virtualenvs/python3/lib/python3.8/site-packages/dislash/application_commands/core.py", line 72, in __call__
    return await self.func(*args, **kwargs)
  File "/home/runner/TheDiscordMathProblemBot/cogs/misc_commands_cog.py", line 362, in get_data
    str(await self._get_json_data_by_user(inter.author)),
  File "/home/runner/TheDiscordMathProblemBot/cogs/misc_commands_cog.py", line 342, in _get_json_data_by_user
    raw_data = await self.cache.get_all_by_author_id(author.id)
  File "/home/runner/TheDiscordMathProblemBot/helpful_modules/problems_module/cache.py", line 916, in get_all_by_author_id
    await cursor.execute(
  File "/opt/virtualenvs/python3/lib/python3.8/site-packages/aiosqlite/cursor.py", line 37, in execute
    await self._execute(self._cursor.execute, sql, parameters)
  File "/opt/virtualenvs/python3/lib/python3.8/site-packages/aiosqlite/cursor.py", line 31, in _execute
    return await self._conn._execute(fn, *args, **kwargs)
  File "/opt/virtualenvs/python3/lib/python3.8/site-packages/aiosqlite/core.py", line 129, in _execute
    return await future
  File "/opt/virtualenvs/python3/lib/python3.8/site-packages/aiosqlite/core.py", line 102, in run
    result = function()
ValueError: parameters are of unsupported type


Thu Dec  9 19:34:42 2021

Traceback (most recent call last):
  File "/opt/virtualenvs/python3/lib/python3.8/site-packages/dislash/application_commands/slash_client.py", line 1275, in _on_slash_command
    await app_command.invoke(inter)
  File "/opt/virtualenvs/python3/lib/python3.8/site-packages/dislash/application_commands/slash_core.py", line 362, in invoke
    raise err
  File "/opt/virtualenvs/python3/lib/python3.8/site-packages/dislash/application_commands/slash_core.py", line 359, in invoke
    await self.invoke_children(interaction)
  File "/opt/virtualenvs/python3/lib/python3.8/site-packages/dislash/application_commands/slash_core.py", line 350, in invoke_children
    raise err
  File "/opt/virtualenvs/python3/lib/python3.8/site-packages/dislash/application_commands/slash_core.py", line 347, in invoke_children
    await subcmd._maybe_cog_call(self._cog, interaction, option)
  File "/opt/virtualenvs/python3/lib/python3.8/site-packages/dislash/application_commands/slash_core.py", line 112, in _maybe_cog_call
    return await self(cog, inter, **kwargs)
  File "/opt/virtualenvs/python3/lib/python3.8/site-packages/dislash/application_commands/core.py", line 72, in __call__
    return await self.func(*args, **kwargs)
  File "/home/runner/TheDiscordMathProblemBot/cogs/misc_commands_cog.py", line 362, in get_data
    str(await self._get_json_data_by_user(inter.author)),
  File "/home/runner/TheDiscordMathProblemBot/cogs/misc_commands_cog.py", line 345, in _get_json_data_by_user
    "Quizzes": [quiz.to_dict() for quiz in raw_data["quizzes"]],
KeyError: 'quizzes'


Thu Dec  9 19:38:12 2021

Traceback (most recent call last):
  File "/opt/virtualenvs/python3/lib/python3.8/site-packages/dislash/application_commands/slash_client.py", line 1275, in _on_slash_command
    await app_command.invoke(inter)
  File "/opt/virtualenvs/python3/lib/python3.8/site-packages/dislash/application_commands/slash_core.py", line 362, in invoke
    raise err
  File "/opt/virtualenvs/python3/lib/python3.8/site-packages/dislash/application_commands/slash_core.py", line 359, in invoke
    await self.invoke_children(interaction)
  File "/opt/virtualenvs/python3/lib/python3.8/site-packages/dislash/application_commands/slash_core.py", line 350, in invoke_children
    raise err
  File "/opt/virtualenvs/python3/lib/python3.8/site-packages/dislash/application_commands/slash_core.py", line 347, in invoke_children
    await subcmd._maybe_cog_call(self._cog, interaction, option)
  File "/opt/virtualenvs/python3/lib/python3.8/site-packages/dislash/application_commands/slash_core.py", line 112, in _maybe_cog_call
    return await self(cog, inter, **kwargs)
  File "/opt/virtualenvs/python3/lib/python3.8/site-packages/dislash/application_commands/core.py", line 72, in __call__
    return await self.func(*args, **kwargs)
  File "/home/runner/TheDiscordMathProblemBot/cogs/misc_commands_cog.py", line 413, in get_data
    BytesIO(orjson.dumps(await self._get_json_data_by_user(inter.author), options = orjson.OPT_INDENT_2)),
  File "/home/runner/TheDiscordMathProblemBot/cogs/misc_commands_cog.py", line 394, in _get_json_data_by_user
    "Quizzes": [quiz.to_dict() for quiz in raw_data["quizzes"]],
KeyError: 'quizzes'


Thu Dec  9 19:42:25 2021

Traceback (most recent call last):
  File "/opt/virtualenvs/python3/lib/python3.8/site-packages/dislash/application_commands/slash_client.py", line 1275, in _on_slash_command
    await app_command.invoke(inter)
  File "/opt/virtualenvs/python3/lib/python3.8/site-packages/dislash/application_commands/slash_core.py", line 362, in invoke
    raise err
  File "/opt/virtualenvs/python3/lib/python3.8/site-packages/dislash/application_commands/slash_core.py", line 359, in invoke
    await self.invoke_children(interaction)
  File "/opt/virtualenvs/python3/lib/python3.8/site-packages/dislash/application_commands/slash_core.py", line 350, in invoke_children
    raise err
  File "/opt/virtualenvs/python3/lib/python3.8/site-packages/dislash/application_commands/slash_core.py", line 347, in invoke_children
    await subcmd._maybe_cog_call(self._cog, interaction, option)
  File "/opt/virtualenvs/python3/lib/python3.8/site-packages/dislash/application_commands/slash_core.py", line 112, in _maybe_cog_call
    return await self(cog, inter, **kwargs)
  File "/opt/virtualenvs/python3/lib/python3.8/site-packages/dislash/application_commands/core.py", line 72, in __call__
    return await self.func(*args, **kwargs)
  File "/home/runner/TheDiscordMathProblemBot/cogs/misc_commands_cog.py", line 413, in get_data
    BytesIO(orjson.dumps(await self._get_json_data_by_user(inter.author), options = orjson.OPT_INDENT_2)),
  File "/home/runner/TheDiscordMathProblemBot/cogs/misc_commands_cog.py", line 396, in _get_json_data_by_user
    submission.to_dict() for submission in raw_data["submissions"]
KeyError: 'submissions'


Thu Dec  9 19:43:04 2021

Traceback (most recent call last):
  File "/opt/virtualenvs/python3/lib/python3.8/site-packages/dislash/application_commands/slash_client.py", line 1275, in _on_slash_command
    await app_command.invoke(inter)
  File "/opt/virtualenvs/python3/lib/python3.8/site-packages/dislash/application_commands/slash_core.py", line 362, in invoke
    raise err
  File "/opt/virtualenvs/python3/lib/python3.8/site-packages/dislash/application_commands/slash_core.py", line 359, in invoke
    await self.invoke_children(interaction)
  File "/opt/virtualenvs/python3/lib/python3.8/site-packages/dislash/application_commands/slash_core.py", line 350, in invoke_children
    raise err
  File "/opt/virtualenvs/python3/lib/python3.8/site-packages/dislash/application_commands/slash_core.py", line 347, in invoke_children
    await subcmd._maybe_cog_call(self._cog, interaction, option)
  File "/opt/virtualenvs/python3/lib/python3.8/site-packages/dislash/application_commands/slash_core.py", line 112, in _maybe_cog_call
    return await self(cog, inter, **kwargs)
  File "/opt/virtualenvs/python3/lib/python3.8/site-packages/dislash/application_commands/core.py", line 72, in __call__
    return await self.func(*args, **kwargs)
  File "/home/runner/TheDiscordMathProblemBot/cogs/misc_commands_cog.py", line 413, in get_data
    BytesIO(orjson.dumps(await self._get_json_data_by_user(inter.author), options = orjson.OPT_INDENT_2)),
  File "/home/runner/TheDiscordMathProblemBot/cogs/misc_commands_cog.py", line 398, in _get_json_data_by_user
    "Problems the user voted for": [problem.to_dict().pop('answers') for problem in problems_user_voted_for],
TypeError: 'NoneType' object is not iterable


Thu Dec  9 21:12:41 2021

Traceback (most recent call last):
  File "/opt/virtualenvs/python3/lib/python3.8/site-packages/dislash/application_commands/slash_client.py", line 1275, in _on_slash_command
    await app_command.invoke(inter)
  File "/opt/virtualenvs/python3/lib/python3.8/site-packages/dislash/application_commands/slash_core.py", line 362, in invoke
    raise err
  File "/opt/virtualenvs/python3/lib/python3.8/site-packages/dislash/application_commands/slash_core.py", line 359, in invoke
    await self.invoke_children(interaction)
  File "/opt/virtualenvs/python3/lib/python3.8/site-packages/dislash/application_commands/slash_core.py", line 350, in invoke_children
    raise err
  File "/opt/virtualenvs/python3/lib/python3.8/site-packages/dislash/application_commands/slash_core.py", line 347, in invoke_children
    await subcmd._maybe_cog_call(self._cog, interaction, option)
  File "/opt/virtualenvs/python3/lib/python3.8/site-packages/dislash/application_commands/slash_core.py", line 112, in _maybe_cog_call
    return await self(cog, inter, **kwargs)
  File "/opt/virtualenvs/python3/lib/python3.8/site-packages/dislash/application_commands/core.py", line 72, in __call__
    return await self.func(*args, **kwargs)
  File "/home/runner/TheDiscordMathProblemBot/cogs/misc_commands_cog.py", line 413, in get_data
    BytesIO(orjson.dumps(await self._get_json_data_by_user(inter.author), options = orjson.OPT_INDENT_2)),
  File "/home/runner/TheDiscordMathProblemBot/cogs/misc_commands_cog.py", line 398, in _get_json_data_by_user
    "Problems the user voted for": [problem.to_dict().pop('answers') for problem in problems_user_voted_for],
TypeError: 'NoneType' object is not iterable


Thu Dec  9 21:18:56 2021

Traceback (most recent call last):
  File "/opt/virtualenvs/python3/lib/python3.8/site-packages/dislash/application_commands/slash_client.py", line 1275, in _on_slash_command
    await app_command.invoke(inter)
  File "/opt/virtualenvs/python3/lib/python3.8/site-packages/dislash/application_commands/slash_core.py", line 362, in invoke
    raise err
  File "/opt/virtualenvs/python3/lib/python3.8/site-packages/dislash/application_commands/slash_core.py", line 359, in invoke
    await self.invoke_children(interaction)
  File "/opt/virtualenvs/python3/lib/python3.8/site-packages/dislash/application_commands/slash_core.py", line 350, in invoke_children
    raise err
  File "/opt/virtualenvs/python3/lib/python3.8/site-packages/dislash/application_commands/slash_core.py", line 347, in invoke_children
    await subcmd._maybe_cog_call(self._cog, interaction, option)
  File "/opt/virtualenvs/python3/lib/python3.8/site-packages/dislash/application_commands/slash_core.py", line 112, in _maybe_cog_call
    return await self(cog, inter, **kwargs)
  File "/opt/virtualenvs/python3/lib/python3.8/site-packages/dislash/application_commands/core.py", line 72, in __call__
    return await self.func(*args, **kwargs)
  File "/home/runner/TheDiscordMathProblemBot/cogs/misc_commands_cog.py", line 415, in get_data
    BytesIO(orjson.dumps(await self._get_json_data_by_user(inter.author), options = orjson.OPT_INDENT_2)),
  File "/home/runner/TheDiscordMathProblemBot/cogs/misc_commands_cog.py", line 400, in _get_json_data_by_user
    "Problems the user voted for": [problem.to_dict(show_answers=False) for problem in problems_user_voted_for],
TypeError: 'NoneType' object is not iterable


Thu Dec  9 21:22:55 2021

Traceback (most recent call last):
  File "/opt/virtualenvs/python3/lib/python3.8/site-packages/dislash/application_commands/slash_client.py", line 1275, in _on_slash_command
    await app_command.invoke(inter)
  File "/opt/virtualenvs/python3/lib/python3.8/site-packages/dislash/application_commands/slash_core.py", line 362, in invoke
    raise err
  File "/opt/virtualenvs/python3/lib/python3.8/site-packages/dislash/application_commands/slash_core.py", line 359, in invoke
    await self.invoke_children(interaction)
  File "/opt/virtualenvs/python3/lib/python3.8/site-packages/dislash/application_commands/slash_core.py", line 350, in invoke_children
    raise err
  File "/opt/virtualenvs/python3/lib/python3.8/site-packages/dislash/application_commands/slash_core.py", line 347, in invoke_children
    await subcmd._maybe_cog_call(self._cog, interaction, option)
  File "/opt/virtualenvs/python3/lib/python3.8/site-packages/dislash/application_commands/slash_core.py", line 112, in _maybe_cog_call
    return await self(cog, inter, **kwargs)
  File "/opt/virtualenvs/python3/lib/python3.8/site-packages/dislash/application_commands/core.py", line 72, in __call__
    return await self.func(*args, **kwargs)
  File "/home/runner/TheDiscordMathProblemBot/cogs/misc_commands_cog.py", line 415, in get_data
    BytesIO(orjson.dumps(await self._get_json_data_by_user(inter.author), options = orjson.OPT_INDENT_2)),
  File "/home/runner/TheDiscordMathProblemBot/cogs/misc_commands_cog.py", line 400, in _get_json_data_by_user
    "Problems the user voted for": [problem.to_dict(show_answers=False) for problem in problems_user_voted_for],
TypeError: 'NoneType' object is not iterable


