Wed Dec 15 15:34:03 2021

Traceback (most recent call last):
  File "/Library/Frameworks/Python.framework/Versions/3.10/lib/python3.10/site-packages/disnake/client.py", line 505, in _run_event
    await coro(*args, **kwargs)
  File "/Users/Samuel/Desktop/github-repos/TheDiscordMathProblemBotRepo/main.py", line 259, in on_slash_command_error
    dict_args = await base_on_error(inter, error)
  File "/Users/Samuel/Desktop/github-repos/TheDiscordMathProblemBotRepo/helpful_modules/threads_or_useful_funcs.py", line 43, in base_on_error
    traceback.format_exception(
TypeError: format_exception() got some positional-only arguments passed as keyword arguments: 'exc'


Wed Dec 15 15:44:05 2021

Traceback (most recent call last):
  File "/Library/Frameworks/Python.framework/Versions/3.10/lib/python3.10/site-packages/disnake/client.py", line 505, in _run_event
    await coro(*args, **kwargs)
  File "/Library/Frameworks/Python.framework/Versions/3.10/lib/python3.10/site-packages/disnake/ext/commands/bot_base.py", line 600, in on_message
    await self.process_commands(message)
  File "/Library/Frameworks/Python.framework/Versions/3.10/lib/python3.10/site-packages/disnake/ext/commands/bot_base.py", line 597, in process_commands
    await self.invoke(ctx)
  File "/Library/Frameworks/Python.framework/Versions/3.10/lib/python3.10/site-packages/disnake/ext/commands/bot_base.py", line 560, in invoke
    await ctx.command.invoke(ctx)
  File "/Library/Frameworks/Python.framework/Versions/3.10/lib/python3.10/site-packages/disnake/ext/commands/core.py", line 921, in invoke
    await self.prepare(ctx)
  File "/Library/Frameworks/Python.framework/Versions/3.10/lib/python3.10/site-packages/disnake/ext/commands/core.py", line 842, in prepare
    if not await self.can_run(ctx):
  File "/Library/Frameworks/Python.framework/Versions/3.10/lib/python3.10/site-packages/disnake/ext/commands/core.py", line 1150, in can_run
    if not await ctx.bot.can_run(ctx):
  File "/Library/Frameworks/Python.framework/Versions/3.10/lib/python3.10/site-packages/disnake/ext/commands/bot_base.py", line 320, in can_run
    return await disnake.utils.async_all(f(ctx) for f in data)  # type: ignore
  File "/Library/Frameworks/Python.framework/Versions/3.10/lib/python3.10/site-packages/disnake/utils.py", line 554, in async_all
    for elem in gen:
  File "/Library/Frameworks/Python.framework/Versions/3.10/lib/python3.10/site-packages/disnake/ext/commands/bot_base.py", line 320, in <genexpr>
    return await disnake.utils.async_all(f(ctx) for f in data)  # type: ignore
TypeError: is_not_blacklisted() takes 0 positional arguments but 1 was given


Wed Dec 15 15:48:17 2021

Traceback (most recent call last):
  File "/Library/Frameworks/Python.framework/Versions/3.10/lib/python3.10/site-packages/disnake/ext/commands/slash_core.py", line 569, in invoke
    await self(inter, **kwargs)
  File "/Library/Frameworks/Python.framework/Versions/3.10/lib/python3.10/site-packages/disnake/ext/commands/base_core.py", line 187, in __call__
    return await self.callback(self.cog, interaction, *args, **kwargs)
  File "/Users/Samuel/Desktop/github-repos/TheDiscordMathProblemBotRepo/cogs/test_cog.py", line 17, in _test
    return await inter.reply('Test')
AttributeError: 'ApplicationCommandInteraction' object has no attribute 'reply'

The above exception was the direct cause of the following exception:

Traceback (most recent call last):
  File "/Library/Frameworks/Python.framework/Versions/3.10/lib/python3.10/site-packages/disnake/ext/commands/interaction_bot_base.py", line 1297, in process_application_commands
    await app_command.invoke(interaction)
  File "/Library/Frameworks/Python.framework/Versions/3.10/lib/python3.10/site-packages/disnake/ext/commands/slash_core.py", line 578, in invoke
    raise CommandInvokeError(exc) from exc
disnake.ext.commands.errors.CommandInvokeError: Command raised an exception: AttributeError: 'ApplicationCommandInteraction' object has no attribute 'reply'


Wed Dec 15 20:16:16 2021

Traceback (most recent call last):
  File "/Library/Frameworks/Python.framework/Versions/3.10/lib/python3.10/site-packages/disnake/client.py", line 505, in _run_event
    await coro(*args, **kwargs)
  File "/Users/Samuel/Desktop/github-repos/TheDiscordMathProblemBotRepo/helpful_modules/custom_bot.py", line 47, in on_ready
    await self._on_ready_func(self)
TypeError: on_ready() takes 0 positional arguments but 1 was given


