Wed Dec 15 15:34:03 2021

Traceback (most recent call last):
  File "/Library/Frameworks/Python.framework/Versions/3.10/lib/python3.10/site-packages/disnake/client.py", line 505, in _run_event
    await coro(*args, **kwargs)
  File "/Users/Samuel/Desktop/github-repos/TheDiscordMathProblemBotRepo/main.py", line 259, in on_slash_command_error
    dict_args = await base_on_error(inter, error)
  File "/Users/Samuel/Desktop/github-repos/TheDiscordMathProblemBotRepo/helpful_modules/threads_or_useful_funcs.py", line 43, in base_on_error
    traceback.format_exception(
TypeError: format_exception() got some positional-only arguments passed as keyword arguments: 'exc'


Wed Dec 15 15:44:05 2021

Traceback (most recent call last):
  File "/Library/Frameworks/Python.framework/Versions/3.10/lib/python3.10/site-packages/disnake/client.py", line 505, in _run_event
    await coro(*args, **kwargs)
  File "/Library/Frameworks/Python.framework/Versions/3.10/lib/python3.10/site-packages/disnake/ext/commands/bot_base.py", line 600, in on_message
    await self.process_commands(message)
  File "/Library/Frameworks/Python.framework/Versions/3.10/lib/python3.10/site-packages/disnake/ext/commands/bot_base.py", line 597, in process_commands
    await self.invoke(ctx)
  File "/Library/Frameworks/Python.framework/Versions/3.10/lib/python3.10/site-packages/disnake/ext/commands/bot_base.py", line 560, in invoke
    await ctx.command.invoke(ctx)
  File "/Library/Frameworks/Python.framework/Versions/3.10/lib/python3.10/site-packages/disnake/ext/commands/core.py", line 921, in invoke
    await self.prepare(ctx)
  File "/Library/Frameworks/Python.framework/Versions/3.10/lib/python3.10/site-packages/disnake/ext/commands/core.py", line 842, in prepare
    if not await self.can_run(ctx):
  File "/Library/Frameworks/Python.framework/Versions/3.10/lib/python3.10/site-packages/disnake/ext/commands/core.py", line 1150, in can_run
    if not await ctx.bot.can_run(ctx):
  File "/Library/Frameworks/Python.framework/Versions/3.10/lib/python3.10/site-packages/disnake/ext/commands/bot_base.py", line 320, in can_run
    return await disnake.utils.async_all(f(ctx) for f in data)  # type: ignore
  File "/Library/Frameworks/Python.framework/Versions/3.10/lib/python3.10/site-packages/disnake/utils.py", line 554, in async_all
    for elem in gen:
  File "/Library/Frameworks/Python.framework/Versions/3.10/lib/python3.10/site-packages/disnake/ext/commands/bot_base.py", line 320, in <genexpr>
    return await disnake.utils.async_all(f(ctx) for f in data)  # type: ignore
TypeError: is_not_blacklisted() takes 0 positional arguments but 1 was given


Wed Dec 15 15:48:17 2021

Traceback (most recent call last):
  File "/Library/Frameworks/Python.framework/Versions/3.10/lib/python3.10/site-packages/disnake/ext/commands/slash_core.py", line 569, in invoke
    await self(inter, **kwargs)
  File "/Library/Frameworks/Python.framework/Versions/3.10/lib/python3.10/site-packages/disnake/ext/commands/base_core.py", line 187, in __call__
    return await self.callback(self.cog, interaction, *args, **kwargs)
  File "/Users/Samuel/Desktop/github-repos/TheDiscordMathProblemBotRepo/cogs/test_cog.py", line 17, in _test
    return await inter.reply('Test')
AttributeError: 'ApplicationCommandInteraction' object has no attribute 'reply'

The above exception was the direct cause of the following exception:

Traceback (most recent call last):
  File "/Library/Frameworks/Python.framework/Versions/3.10/lib/python3.10/site-packages/disnake/ext/commands/interaction_bot_base.py", line 1297, in process_application_commands
    await app_command.invoke(interaction)
  File "/Library/Frameworks/Python.framework/Versions/3.10/lib/python3.10/site-packages/disnake/ext/commands/slash_core.py", line 578, in invoke
    raise CommandInvokeError(exc) from exc
disnake.ext.commands.errors.CommandInvokeError: Command raised an exception: AttributeError: 'ApplicationCommandInteraction' object has no attribute 'reply'


Wed Dec 15 20:16:16 2021

Traceback (most recent call last):
  File "/Library/Frameworks/Python.framework/Versions/3.10/lib/python3.10/site-packages/disnake/client.py", line 505, in _run_event
    await coro(*args, **kwargs)
  File "/Users/Samuel/Desktop/github-repos/TheDiscordMathProblemBotRepo/helpful_modules/custom_bot.py", line 47, in on_ready
    await self._on_ready_func(self)
TypeError: on_ready() takes 0 positional arguments but 1 was given


Wed Dec 15 20:52:31 2021

Traceback (most recent call last):
  File "/Library/Frameworks/Python.framework/Versions/3.10/lib/python3.10/site-packages/disnake/ext/commands/slash_core.py", line 569, in invoke
    await self(inter, **kwargs)
  File "/Library/Frameworks/Python.framework/Versions/3.10/lib/python3.10/site-packages/disnake/ext/commands/base_core.py", line 187, in __call__
    return await self.callback(self.cog, interaction, *args, **kwargs)
  File "/Users/Samuel/Desktop/github-repos/TheDiscordMathProblemBotRepo/cogs/problems_cog.py", line 631, in check_answer
    problem = await self.bot.cache.get_problem(
  File "/Users/Samuel/Desktop/github-repos/TheDiscordMathProblemBotRepo/helpful_modules/problems_module/cache.py", line 366, in get_problem
    raise TypeError(
TypeError: guild_id isn't an integer and this will cause issues in SQL!

The above exception was the direct cause of the following exception:

Traceback (most recent call last):
  File "/Library/Frameworks/Python.framework/Versions/3.10/lib/python3.10/site-packages/disnake/ext/commands/interaction_bot_base.py", line 1297, in process_application_commands
    await app_command.invoke(interaction)
  File "/Library/Frameworks/Python.framework/Versions/3.10/lib/python3.10/site-packages/disnake/ext/commands/slash_core.py", line 578, in invoke
    raise CommandInvokeError(exc) from exc
disnake.ext.commands.errors.CommandInvokeError: Command raised an exception: TypeError: guild_id isn't an integer and this will cause issues in SQL!


Wed Dec 15 21:33:19 2021

Traceback (most recent call last):
  File "/Library/Frameworks/Python.framework/Versions/3.10/lib/python3.10/site-packages/disnake/ext/commands/slash_core.py", line 569, in invoke
    await self(inter, **kwargs)
  File "/Library/Frameworks/Python.framework/Versions/3.10/lib/python3.10/site-packages/disnake/ext/commands/base_core.py", line 187, in __call__
    return await self.callback(self.cog, interaction, *args, **kwargs)
  File "/Users/Samuel/Desktop/github-repos/TheDiscordMathProblemBotRepo/cogs/problems_cog.py", line 631, in check_answer
  File "/Users/Samuel/Desktop/github-repos/TheDiscordMathProblemBotRepo/helpful_modules/problems_module/cache.py", line 366, in get_problem
    raise TypeError(
TypeError: guild_id isn't an integer and this will cause issues in SQL!

The above exception was the direct cause of the following exception:

Traceback (most recent call last):
  File "/Library/Frameworks/Python.framework/Versions/3.10/lib/python3.10/site-packages/disnake/ext/commands/interaction_bot_base.py", line 1297, in process_application_commands
    await app_command.invoke(interaction)
  File "/Library/Frameworks/Python.framework/Versions/3.10/lib/python3.10/site-packages/disnake/ext/commands/slash_core.py", line 578, in invoke
    raise CommandInvokeError(exc) from exc
disnake.ext.commands.errors.CommandInvokeError: Command raised an exception: TypeError: guild_id isn't an integer and this will cause issues in SQL!


Wed Dec 15 21:34:06 2021

Traceback (most recent call last):
  File "/Library/Frameworks/Python.framework/Versions/3.10/lib/python3.10/site-packages/disnake/ext/commands/slash_core.py", line 569, in invoke
    await self(inter, **kwargs)
  File "/Library/Frameworks/Python.framework/Versions/3.10/lib/python3.10/site-packages/disnake/ext/commands/base_core.py", line 187, in __call__
    return await self.callback(self.cog, interaction, *args, **kwargs)
  File "/Users/Samuel/Desktop/github-repos/TheDiscordMathProblemBotRepo/cogs/problems_cog.py", line 633, in check_answer
    problem = await self.bot.cache.get_problem(
  File "/Users/Samuel/Desktop/github-repos/TheDiscordMathProblemBotRepo/helpful_modules/problems_module/cache.py", line 366, in get_problem
    raise TypeError(
TypeError: guild_id isn't an integer and this will cause issues in SQL!

The above exception was the direct cause of the following exception:

Traceback (most recent call last):
  File "/Library/Frameworks/Python.framework/Versions/3.10/lib/python3.10/site-packages/disnake/ext/commands/interaction_bot_base.py", line 1297, in process_application_commands
    await app_command.invoke(interaction)
  File "/Library/Frameworks/Python.framework/Versions/3.10/lib/python3.10/site-packages/disnake/ext/commands/slash_core.py", line 578, in invoke
    raise CommandInvokeError(exc) from exc
disnake.ext.commands.errors.CommandInvokeError: Command raised an exception: TypeError: guild_id isn't an integer and this will cause issues in SQL!


Wed Dec 15 21:42:31 2021

Traceback (most recent call last):
  File "/Library/Frameworks/Python.framework/Versions/3.10/lib/python3.10/site-packages/disnake/ext/commands/slash_core.py", line 569, in invoke
    await self(inter, **kwargs)
  File "/Library/Frameworks/Python.framework/Versions/3.10/lib/python3.10/site-packages/disnake/ext/commands/base_core.py", line 187, in __call__
    return await self.callback(self.cog, interaction, *args, **kwargs)
  File "/Users/Samuel/Desktop/github-repos/TheDiscordMathProblemBotRepo/cogs/problems_cog.py", line 633, in check_answer
    problem = await self.bot.cache.get_problem(
  File "/Users/Samuel/Desktop/github-repos/TheDiscordMathProblemBotRepo/helpful_modules/problems_module/cache.py", line 366, in get_problem
    raise TypeError(
TypeError: guild_id isn't an integer and this will cause issues in SQL!

The above exception was the direct cause of the following exception:

Traceback (most recent call last):
  File "/Library/Frameworks/Python.framework/Versions/3.10/lib/python3.10/site-packages/disnake/ext/commands/interaction_bot_base.py", line 1297, in process_application_commands
    await app_command.invoke(interaction)
  File "/Library/Frameworks/Python.framework/Versions/3.10/lib/python3.10/site-packages/disnake/ext/commands/slash_core.py", line 578, in invoke
    raise CommandInvokeError(exc) from exc
disnake.ext.commands.errors.CommandInvokeError: Command raised an exception: TypeError: guild_id isn't an integer and this will cause issues in SQL!


Wed Dec 15 21:42:31 2021

Traceback (most recent call last):
  File "/Library/Frameworks/Python.framework/Versions/3.10/lib/python3.10/site-packages/disnake/client.py", line 505, in _run_event
    await coro(*args, **kwargs)
  File "/Users/Samuel/Desktop/github-repos/TheDiscordMathProblemBotRepo/main.py", line 264, in on_slash_command_error
    return await inter.send(**dict_args)
  File "/Library/Frameworks/Python.framework/Versions/3.10/lib/python3.10/site-packages/disnake/interactions/base.py", line 507, in send
    await sender(  # type: ignore
  File "/Library/Frameworks/Python.framework/Versions/3.10/lib/python3.10/site-packages/disnake/interactions/base.py", line 730, in send_message
    await adapter.create_interaction_response(
  File "/Library/Frameworks/Python.framework/Versions/3.10/lib/python3.10/site-packages/disnake/webhook/async_.py", line 211, in request
    raise HTTPException(response, data)
disnake.errors.HTTPException: 400 Bad Request (error code: 50035): Invalid Form Body
In data.content: Must be 2000 or fewer in length.


Wed Dec 15 21:44:44 2021

Traceback (most recent call last):
  File "/Library/Frameworks/Python.framework/Versions/3.10/lib/python3.10/site-packages/disnake/ext/commands/interaction_bot_base.py", line 1297, in process_application_commands
    await app_command.invoke(interaction)
  File "/Library/Frameworks/Python.framework/Versions/3.10/lib/python3.10/site-packages/disnake/ext/commands/slash_core.py", line 557, in invoke
    await self.prepare(inter)
  File "/Library/Frameworks/Python.framework/Versions/3.10/lib/python3.10/site-packages/disnake/ext/commands/base_core.py", line 205, in prepare
    raise CheckFailure(f"The check functions for command {self.qualified_name!r} failed.")
disnake.ext.commands.errors.CheckFailure: The check functions for command 'raise_error' failed.


Wed Dec 15 21:48:12 2021

Traceback (most recent call last):
  File "/Library/Frameworks/Python.framework/Versions/3.10/lib/python3.10/site-packages/disnake/ext/commands/interaction_bot_base.py", line 1297, in process_application_commands
    await app_command.invoke(interaction)
  File "/Library/Frameworks/Python.framework/Versions/3.10/lib/python3.10/site-packages/disnake/ext/commands/slash_core.py", line 557, in invoke
    await self.prepare(inter)
  File "/Library/Frameworks/Python.framework/Versions/3.10/lib/python3.10/site-packages/disnake/ext/commands/base_core.py", line 205, in prepare
    raise CheckFailure(f"The check functions for command {self.qualified_name!r} failed.")
disnake.ext.commands.errors.CheckFailure: The check functions for command 'raise_error' failed.


Wed Dec 15 21:49:38 2021

Traceback (most recent call last):
  File "/Library/Frameworks/Python.framework/Versions/3.10/lib/python3.10/site-packages/disnake/ext/commands/interaction_bot_base.py", line 1297, in process_application_commands
    await app_command.invoke(interaction)
  File "/Library/Frameworks/Python.framework/Versions/3.10/lib/python3.10/site-packages/disnake/ext/commands/slash_core.py", line 557, in invoke
    await self.prepare(inter)
  File "/Library/Frameworks/Python.framework/Versions/3.10/lib/python3.10/site-packages/disnake/ext/commands/base_core.py", line 205, in prepare
    raise CheckFailure(f"The check functions for command {self.qualified_name!r} failed.")
disnake.ext.commands.errors.CheckFailure: The check functions for command 'raise_error' failed.


Wed Dec 15 21:52:13 2021

Traceback (most recent call last):
  File "/Library/Frameworks/Python.framework/Versions/3.10/lib/python3.10/site-packages/disnake/ext/commands/slash_core.py", line 569, in invoke
    await self(inter, **kwargs)
  File "/Library/Frameworks/Python.framework/Versions/3.10/lib/python3.10/site-packages/disnake/ext/commands/base_core.py", line 187, in __call__
    return await self.callback(self.cog, interaction, *args, **kwargs)
  File "/Users/Samuel/Desktop/github-repos/TheDiscordMathProblemBotRepo/cogs/problems_cog.py", line 633, in check_answer
    problem = await self.bot.cache.get_problem(
  File "/Users/Samuel/Desktop/github-repos/TheDiscordMathProblemBotRepo/helpful_modules/problems_module/cache.py", line 366, in get_problem
    raise TypeError(
TypeError: guild_id isn't an integer and this will cause issues in SQL!

The above exception was the direct cause of the following exception:

Traceback (most recent call last):
  File "/Library/Frameworks/Python.framework/Versions/3.10/lib/python3.10/site-packages/disnake/ext/commands/interaction_bot_base.py", line 1297, in process_application_commands
    await app_command.invoke(interaction)
  File "/Library/Frameworks/Python.framework/Versions/3.10/lib/python3.10/site-packages/disnake/ext/commands/slash_core.py", line 578, in invoke
    raise CommandInvokeError(exc) from exc
disnake.ext.commands.errors.CommandInvokeError: Command raised an exception: TypeError: guild_id isn't an integer and this will cause issues in SQL!


Wed Dec 15 21:57:07 2021

Traceback (most recent call last):
  File "/Library/Frameworks/Python.framework/Versions/3.10/lib/python3.10/site-packages/disnake/ext/commands/slash_core.py", line 569, in invoke
    await self(inter, **kwargs)
  File "/Library/Frameworks/Python.framework/Versions/3.10/lib/python3.10/site-packages/disnake/ext/commands/base_core.py", line 187, in __call__
    return await self.callback(self.cog, interaction, *args, **kwargs)
  File "/Users/Samuel/Desktop/github-repos/TheDiscordMathProblemBotRepo/cogs/problems_cog.py", line 633, in check_answer
    problem = await self.bot.cache.get_problem(
  File "/Users/Samuel/Desktop/github-repos/TheDiscordMathProblemBotRepo/helpful_modules/problems_module/cache.py", line 366, in get_problem
    raise TypeError(
TypeError: guild_id isn't an integer and this will cause issues in SQL!

The above exception was the direct cause of the following exception:

Traceback (most recent call last):
  File "/Library/Frameworks/Python.framework/Versions/3.10/lib/python3.10/site-packages/disnake/ext/commands/interaction_bot_base.py", line 1297, in process_application_commands
    await app_command.invoke(interaction)
  File "/Library/Frameworks/Python.framework/Versions/3.10/lib/python3.10/site-packages/disnake/ext/commands/slash_core.py", line 578, in invoke
    raise CommandInvokeError(exc) from exc
disnake.ext.commands.errors.CommandInvokeError: Command raised an exception: TypeError: guild_id isn't an integer and this will cause issues in SQL!


Wed Dec 15 21:59:23 2021

Traceback (most recent call last):
  File "/Library/Frameworks/Python.framework/Versions/3.10/lib/python3.10/site-packages/disnake/ext/commands/interaction_bot_base.py", line 1297, in process_application_commands
    await app_command.invoke(interaction)
  File "/Library/Frameworks/Python.framework/Versions/3.10/lib/python3.10/site-packages/disnake/ext/commands/slash_core.py", line 557, in invoke
    await self.prepare(inter)
  File "/Library/Frameworks/Python.framework/Versions/3.10/lib/python3.10/site-packages/disnake/ext/commands/base_core.py", line 211, in prepare
    self._prepare_cooldowns(inter)
  File "/Library/Frameworks/Python.framework/Versions/3.10/lib/python3.10/site-packages/disnake/ext/commands/base_core.py", line 199, in _prepare_cooldowns
    raise CommandOnCooldown(bucket, retry_after, self._buckets.type)  # type: ignore
disnake.ext.commands.errors.CommandOnCooldown: You are on cooldown. Try again in 146.16s


Wed Dec 15 21:59:27 2021

Traceback (most recent call last):
  File "/Library/Frameworks/Python.framework/Versions/3.10/lib/python3.10/site-packages/disnake/ext/commands/interaction_bot_base.py", line 1297, in process_application_commands
    await app_command.invoke(interaction)
  File "/Library/Frameworks/Python.framework/Versions/3.10/lib/python3.10/site-packages/disnake/ext/commands/slash_core.py", line 557, in invoke
    await self.prepare(inter)
  File "/Library/Frameworks/Python.framework/Versions/3.10/lib/python3.10/site-packages/disnake/ext/commands/base_core.py", line 211, in prepare
    self._prepare_cooldowns(inter)
  File "/Library/Frameworks/Python.framework/Versions/3.10/lib/python3.10/site-packages/disnake/ext/commands/base_core.py", line 199, in _prepare_cooldowns
    raise CommandOnCooldown(bucket, retry_after, self._buckets.type)  # type: ignore
disnake.ext.commands.errors.CommandOnCooldown: You are on cooldown. Try again in 142.19s


Wed Dec 15 22:04:54 2021

Traceback (most recent call last):
  File "/Library/Frameworks/Python.framework/Versions/3.10/lib/python3.10/site-packages/disnake/ext/commands/slash_core.py", line 569, in invoke
    await self(inter, **kwargs)
  File "/Library/Frameworks/Python.framework/Versions/3.10/lib/python3.10/site-packages/disnake/ext/commands/base_core.py", line 187, in __call__
    return await self.callback(self.cog, interaction, *args, **kwargs)
  File "/Users/Samuel/Desktop/github-repos/TheDiscordMathProblemBotRepo/cogs/problems_cog.py", line 632, in check_answer
    print(inter.guild.id.__class__.__name__)
AttributeError: 'NoneType' object has no attribute 'id'

The above exception was the direct cause of the following exception:

Traceback (most recent call last):
  File "/Library/Frameworks/Python.framework/Versions/3.10/lib/python3.10/site-packages/disnake/ext/commands/interaction_bot_base.py", line 1297, in process_application_commands
    await app_command.invoke(interaction)
  File "/Library/Frameworks/Python.framework/Versions/3.10/lib/python3.10/site-packages/disnake/ext/commands/slash_core.py", line 578, in invoke
    raise CommandInvokeError(exc) from exc
disnake.ext.commands.errors.CommandInvokeError: Command raised an exception: AttributeError: 'NoneType' object has no attribute 'id'


